<?xml version="1.0"?>
<robot xmlns:xacro="http://www.ros.org/wiki/xacro">
  <link
    name="base_link">
    <inertial>
      <origin
        xyz="0.1124 5.6052E-06 -0.19648"
        rpy="0 0 0" />
      <mass
        value="6.5004" />
      <inertia
        ixx="0.16675"
        ixy="-3.2234E-08"
        ixz="0.0061049"
        iyy="0.32249"
        iyz="8.7361E-08"
        izz="0.46641" />
    </inertial>
    <visual>
      <origin
        xyz="0 0 0"
        rpy="0 0 0" />
      <geometry>
        <mesh
          filename="file://$(find carta)/meshes/base_link.STL" />
      </geometry>
      <material
        name="">
        <color
          rgba="0 1 0 1" />
      </material>
    </visual>
    <collision>
      <origin
        xyz="0 0 0"
        rpy="0 0 0" />
      <geometry>
        <mesh
          filename="file://$(find carta)/meshes/base_link.STL" />
      </geometry>
    </collision>
  </link>
  <link
    name="right_wheel">
    <inertial>
      <origin
        xyz="0.00072185 -9.4034E-05 -4.3345E-05"
        rpy="0 0 0" />
      <mass
        value="7.9806" />
      <inertia
        ixx="0.068768"
        ixy="6.2572E-05"
        ixz="-2.0721E-05"
        iyy="0.068422"
        iyz="-1.2057E-05"
        izz="0.12823" />
    </inertial>
    <visual>
      <origin
        xyz="0 0 0"
        rpy="0 0 0" />
      <geometry>
        <mesh
          filename="file://$(find carta)/meshes/right_wheel.STL" />
      </geometry>
      <material
        name="">
        <color
          rgba="0 0 0 1" />
      </material>
    </visual>
    <collision>
      <origin
        xyz="0 0 0"
        rpy="0 0 0" />
      <geometry>
        <mesh
          filename="file://$(find carta)/meshes/right_wheel.STL" />
      </geometry>
    </collision>
  </link>
  <joint
    name="right_wheel_joint"
    type="continuous">
    <origin
      xyz="-0.39103 -0.19663 -0.64082"
      rpy="1.5708 0.038457 0" />
    <parent
      link="base_link" />
    <child
      link="right_wheel" />
    <axis
      xyz="0 0 1" />
    <!-- <limit
      effort="10"
      velocity="10" />
    <dynamics
      damping="0.1"
      friction="0.1" /> -->
  </joint>
  <link
    name="left_wheel">
    <inertial>
      <origin
        xyz="-0.00067704 -0.00016151 -4.335E-05"
        rpy="0 0 0" />
      <mass
        value="7.9806" />
      <inertia
        ixx="0.068685"
        ixy="0.00016087"
        ixz="1.5203E-05"
        iyy="0.068505"
        iyz="1.8533E-05"
        izz="0.12823" />
    </inertial>
    <visual>
      <origin
        xyz="0 0 0"
        rpy="0 0 0" />
      <geometry>
        <mesh
          filename="file://$(find carta)/meshes/left_wheel.STL" />
      </geometry>
      <material
        name="">
        <color
          rgba="0 0 0 1" />
      </material>
    </visual>
    <collision>
      <origin
        xyz="0 0 0"
        rpy="0 0 0" />
      <geometry>
        <mesh
          filename="file://$(find carta)/meshes/left_wheel.STL" />
      </geometry>
    </collision>
  </link>
  <joint
    name="left_wheel_joint"
    type="continuous">
    <origin
      xyz="-0.391 0.20337 -0.64083"
      rpy="1.5708 0.038457 0" />
    <parent
      link="base_link" />
    <child
      link="left_wheel" />
    <axis
      xyz="0 0 1" />
    <!-- <limit
      effort="10"
      velocity="10" />
    <dynamics
      damping="0.1"
      friction="0.1" /> -->
  </joint>
  <link
    name="right_caster">
    <inertial>
      <origin
        xyz="3.636E-15 -4.996E-16 0.0095082"
        rpy="0 0 0" />
      <mass
        value="4.8125" />
      <inertia
        ixx="0.045063"
        ixy="1.3986E-17"
        ixz="1.5592E-14"
        iyy="0.045063"
        iyz="-1.9849E-15"
        izz="0.084869" />
    </inertial>
    <visual>
      <origin
        xyz="0 0 0"
        rpy="0 0 0" />
      <geometry>
        <mesh
          filename="file://$(find carta)/meshes/right_caster.STL" />
      </geometry>
      <material
        name="">
        <color
          rgba="0 0 0 1" />
      </material>
    </visual>
    <collision>
      <origin
        xyz="0 0 0"
        rpy="0 0 0" />
      <geometry>
        <mesh
          filename="file://$(find carta)/meshes/right_caster.STL" />
      </geometry>
    </collision>
  </link>
  <joint
    name="right_caster_joint"
    type="continuous">
    <origin
      xyz="0.1856 -0.19149 -0.67086"
      rpy="1.5708 0.038457 0" />
    <parent
      link="base_link" />
    <child
      link="right_caster" />
    <axis
      xyz="0 0 1" />
    <!-- <limit
      effort="10"
      velocity="10" />
    <dynamics
      damping="0.1"
      friction="0.1" /> -->
  </joint>
  <link
    name="left_caster">
    <inertial>
      <origin
        xyz="-3.6082E-15 5.5511E-16 -0.0095082"
        rpy="0 0 0" />
      <mass
        value="4.8125" />
      <inertia
        ixx="0.045063"
        ixy="2.3852E-18"
        ixz="1.5584E-14"
        iyy="0.045063"
        iyz="-1.9851E-15"
        izz="0.084869" />
    </inertial>
    <visual>
      <origin
        xyz="0 0 0"
        rpy="0 0 0" />
      <geometry>
        <mesh
          filename="file://$(find carta)/meshes/left_caster.STL" />
      </geometry>
      <material
        name="">
        <color
          rgba="0 0 0 1" />
      </material>
    </visual>
    <collision>
      <origin
        xyz="0 0 0"
        rpy="0 0 0" />
      <geometry>
        <mesh
          filename="file://$(find carta)/meshes/left_caster.STL" />
      </geometry>
    </collision>
  </link>
  <joint
    name="left_caster_wheel"
    type="continuous">
    <origin
      xyz="0.1856 0.19149 -0.67086"
      rpy="1.5708 0.038457 0" />
    <parent
      link="base_link" />
    <child
      link="left_caster" />
    <axis
      xyz="0 0 -1" />
    <!-- <limit
      effort="10"
      velocity="10" />
    <dynamics
      damping="0.1"
      friction="0.1" /> -->
  </joint>
</robot>
 
